INFO 2025-10-31 00:24:20,444 autoreload 34390 8539578688 Watching for file changes with StatReloader
INFO 2025-10-31 00:25:28,574 autoreload 34390 8539578688 /Users/david.galluzzo/source2target-app-v2/backend/mapping/views.py changed, reloading.
INFO 2025-10-31 00:25:28,817 autoreload 34473 8539578688 Watching for file changes with StatReloader
INFO 2025-10-31 00:30:01,621 autoreload 34473 8539578688 /Users/david.galluzzo/source2target-app-v2/backend/mapping/services/databricks_service.py changed, reloading.
INFO 2025-10-31 00:30:01,930 autoreload 36455 8539578688 Watching for file changes with StatReloader
WARNING 2025-10-31 00:30:07,696 databricks_service 36455 8539578688 Databricks credentials not configured
INFO 2025-10-31 00:30:11,949 autoreload 36455 8539578688 /Users/david.galluzzo/source2target-app-v2/backend/mapping/services/databricks_service.py changed, reloading.
INFO 2025-10-31 00:30:12,292 autoreload 36471 8539578688 Watching for file changes with StatReloader
WARNING 2025-10-31 00:30:12,826 databricks_service 36471 8539578688 Databricks credentials not configured
INFO 2025-10-31 00:30:21,267 autoreload 36471 8539578688 /Users/david.galluzzo/source2target-app-v2/backend/mapping/services/databricks_service.py changed, reloading.
INFO 2025-10-31 00:30:21,668 autoreload 36475 8539578688 Watching for file changes with StatReloader
WARNING 2025-10-31 00:30:22,201 databricks_service 36475 8539578688 Databricks credentials not configured
INFO 2025-10-31 00:30:34,841 autoreload 36475 8539578688 /Users/david.galluzzo/source2target-app-v2/backend/mapping/services/databricks_service.py changed, reloading.
INFO 2025-10-31 00:30:35,206 autoreload 36486 8539578688 Watching for file changes with StatReloader
WARNING 2025-10-31 00:30:35,727 databricks_service 36486 8539578688 Databricks credentials not configured
INFO 2025-10-31 00:30:43,123 autoreload 36486 8539578688 /Users/david.galluzzo/source2target-app-v2/backend/mapping/services/databricks_service.py changed, reloading.
INFO 2025-10-31 00:30:43,498 autoreload 36490 8539578688 Watching for file changes with StatReloader
WARNING 2025-10-31 00:30:44,033 databricks_service 36490 8539578688 Databricks credentials not configured
INFO 2025-10-31 00:30:52,453 autoreload 36490 8539578688 /Users/david.galluzzo/source2target-app-v2/backend/mapping/services/databricks_service.py changed, reloading.
INFO 2025-10-31 00:30:52,796 autoreload 36494 8539578688 Watching for file changes with StatReloader
WARNING 2025-10-31 00:30:53,316 databricks_service 36494 8539578688 Databricks credentials not configured
INFO 2025-10-31 00:30:58,619 autoreload 36494 8539578688 /Users/david.galluzzo/source2target-app-v2/backend/mapping/services/databricks_service.py changed, reloading.
INFO 2025-10-31 00:30:58,968 autoreload 36500 8539578688 Watching for file changes with StatReloader
WARNING 2025-10-31 00:30:59,493 databricks_service 36500 8539578688 Databricks credentials not configured
WARNING 2025-10-31 00:31:05,413 databricks_service 36514 8539578688 Databricks credentials not configured
INFO 2025-10-31 00:31:11,614 autoreload 36564 8539578688 Watching for file changes with StatReloader
WARNING 2025-10-31 00:31:12,097 databricks_service 36564 8539578688 Databricks credentials not configured
INFO 2025-10-31 00:31:48,785 autoreload 36500 8539578688 /Users/david.galluzzo/source2target-app-v2/backend/wsgi.py changed, reloading.
INFO 2025-10-31 00:31:49,117 autoreload 36642 8539578688 Watching for file changes with StatReloader
WARNING 2025-10-31 00:31:49,617 databricks_service 36642 8539578688 Databricks credentials not configured
INFO 2025-10-31 00:34:21,081 autoreload 36642 8539578688 /Users/david.galluzzo/source2target-app-v2/backend_env/lib/python3.14/site-packages/pandas/plotting/_misc.py changed, reloading.
INFO 2025-10-31 00:34:21,483 autoreload 37084 8539578688 Watching for file changes with StatReloader
WARNING 2025-10-31 00:34:26,205 databricks_service 37084 8539578688 Databricks credentials not configured
INFO 2025-10-31 00:34:36,717 autoreload 37084 8539578688 /Users/david.galluzzo/source2target-app-v2/backend/settings.py changed, reloading.
INFO 2025-10-31 00:34:37,152 autoreload 37109 8539578688 Watching for file changes with StatReloader
WARNING 2025-10-31 00:34:37,717 databricks_service 37109 8539578688 Databricks credentials not configured
INFO 2025-10-31 00:35:13,341 autoreload 37109 8539578688 /Users/david.galluzzo/source2target-app-v2/backend/mapping/services/databricks_service.py changed, reloading.
INFO 2025-10-31 00:35:13,779 autoreload 37131 8539578688 Watching for file changes with StatReloader
ERROR 2025-10-31 00:35:14,525 databricks_service 37131 8539578688 Failed to initialize Databricks clients: default auth: cannot configure default credentials, please check https://docs.databricks.com/en/dev-tools/auth.html#databricks-client-unified-authentication to configure credentials for your preferred authentication method. Config: host=https://Acuity-oz-test-ue1.cloud.databricks.com
WARNING 2025-10-31 00:35:14,525 databricks_service 37131 8539578688 Databricks integration will not be available
INFO 2025-10-31 00:35:23,991 autoreload 37131 8539578688 /Users/david.galluzzo/source2target-app-v2/backend/mapping/services/databricks_service.py changed, reloading.
INFO 2025-10-31 00:35:24,433 autoreload 37139 8539578688 Watching for file changes with StatReloader
ERROR 2025-10-31 00:35:25,017 databricks_service 37139 8539578688 Failed to initialize Databricks clients: default auth: cannot configure default credentials, please check https://docs.databricks.com/en/dev-tools/auth.html#databricks-client-unified-authentication to configure credentials for your preferred authentication method. Config: host=https://Acuity-oz-test-ue1.cloud.databricks.com
WARNING 2025-10-31 00:35:25,017 databricks_service 37139 8539578688 Databricks integration will not be available
ERROR 2025-10-31 00:35:30,288 databricks_service 37153 8539578688 Failed to initialize Databricks clients: default auth: cannot configure default credentials, please check https://docs.databricks.com/en/dev-tools/auth.html#databricks-client-unified-authentication to configure credentials for your preferred authentication method. Config: host=https://Acuity-oz-test-ue1.cloud.databricks.com
WARNING 2025-10-31 00:35:30,288 databricks_service 37153 8539578688 Databricks integration will not be available
INFO 2025-10-31 00:36:05,244 autoreload 37287 8539578688 Watching for file changes with StatReloader
INFO 2025-10-31 00:36:05,757 databricks_service 37287 8539578688 Databricks Workspace Client initialized with token authentication
INFO 2025-10-31 00:36:16,333 autoreload 37139 8539578688 /Users/david.galluzzo/source2target-app-v2/backend/mapping/services/databricks_service.py changed, reloading.
INFO 2025-10-31 00:36:16,692 autoreload 37295 8539578688 Watching for file changes with StatReloader
INFO 2025-10-31 00:36:17,226 databricks_service 37295 8539578688 Databricks Workspace Client initialized with token authentication
INFO 2025-10-31 00:39:48,493 basehttp 37295 6167146496 "GET /api/docs/swagger/ HTTP/1.1" 200 4675
INFO 2025-10-31 00:39:48,948 basehttp 37295 6167146496 "GET /api/docs/schema/ HTTP/1.1" 200 218065
INFO 2025-10-31 00:42:02,730 basehttp 37295 6167146496 "OPTIONS /api/accounts/auth/login/ HTTP/1.1" 200 0
ERROR 2025-10-31 00:42:02,754 log 37295 6167146496 Internal Server Error: /api/accounts/auth/login/
Traceback (most recent call last):
  File "/Users/david.galluzzo/source2target-app-v2/backend_env/lib/python3.14/site-packages/django/db/backends/utils.py", line 105, in _execute
    return self.cursor.execute(sql, params)
           ~~~~~~~~~~~~~~~~~~~^^^^^^^^^^^^^
  File "/Users/david.galluzzo/source2target-app-v2/backend_env/lib/python3.14/site-packages/django/db/backends/sqlite3/base.py", line 360, in execute
    return super().execute(query, params)
           ~~~~~~~~~~~~~~~^^^^^^^^^^^^^^^
sqlite3.OperationalError: no such table: auth_user

The above exception was the direct cause of the following exception:

Traceback (most recent call last):
  File "/Users/david.galluzzo/source2target-app-v2/backend_env/lib/python3.14/site-packages/django/core/handlers/exception.py", line 55, in inner
    response = get_response(request)
  File "/Users/david.galluzzo/source2target-app-v2/backend_env/lib/python3.14/site-packages/django/core/handlers/base.py", line 197, in _get_response
    response = wrapped_callback(request, *callback_args, **callback_kwargs)
  File "/Users/david.galluzzo/source2target-app-v2/backend_env/lib/python3.14/site-packages/django/views/decorators/csrf.py", line 65, in _view_wrapper
    return view_func(request, *args, **kwargs)
  File "/Users/david.galluzzo/source2target-app-v2/backend_env/lib/python3.14/site-packages/django/views/generic/base.py", line 105, in view
    return self.dispatch(request, *args, **kwargs)
           ~~~~~~~~~~~~~^^^^^^^^^^^^^^^^^^^^^^^^^^
  File "/Users/david.galluzzo/source2target-app-v2/backend_env/lib/python3.14/site-packages/rest_framework/views.py", line 515, in dispatch
    response = self.handle_exception(exc)
  File "/Users/david.galluzzo/source2target-app-v2/backend_env/lib/python3.14/site-packages/rest_framework/views.py", line 475, in handle_exception
    self.raise_uncaught_exception(exc)
    ~~~~~~~~~~~~~~~~~~~~~~~~~~~~~^^^^^
  File "/Users/david.galluzzo/source2target-app-v2/backend_env/lib/python3.14/site-packages/rest_framework/views.py", line 486, in raise_uncaught_exception
    raise exc
  File "/Users/david.galluzzo/source2target-app-v2/backend_env/lib/python3.14/site-packages/rest_framework/views.py", line 512, in dispatch
    response = handler(request, *args, **kwargs)
  File "/Users/david.galluzzo/source2target-app-v2/backend/accounts/views.py", line 44, in post
    response = super().post(request, *args, **kwargs)
  File "/Users/david.galluzzo/source2target-app-v2/backend_env/lib/python3.14/site-packages/rest_framework_simplejwt/views.py", line 46, in post
    serializer.is_valid(raise_exception=True)
    ~~~~~~~~~~~~~~~~~~~^^^^^^^^^^^^^^^^^^^^^^
  File "/Users/david.galluzzo/source2target-app-v2/backend_env/lib/python3.14/site-packages/rest_framework/serializers.py", line 225, in is_valid
    self._validated_data = self.run_validation(self.initial_data)
                           ~~~~~~~~~~~~~~~~~~~^^^^^^^^^^^^^^^^^^^
  File "/Users/david.galluzzo/source2target-app-v2/backend_env/lib/python3.14/site-packages/rest_framework/serializers.py", line 447, in run_validation
    value = self.validate(value)
  File "/Users/david.galluzzo/source2target-app-v2/backend/accounts/serializers.py", line 36, in validate
    user = User.objects.get(email=email)
  File "/Users/david.galluzzo/source2target-app-v2/backend_env/lib/python3.14/site-packages/django/db/models/manager.py", line 87, in manager_method
    return getattr(self.get_queryset(), name)(*args, **kwargs)
           ~~~~~~~~~~~~~~~~~~~~~~~~~~~~~~~~~~^^^^^^^^^^^^^^^^^
  File "/Users/david.galluzzo/source2target-app-v2/backend_env/lib/python3.14/site-packages/django/db/models/query.py", line 629, in get
    num = len(clone)
  File "/Users/david.galluzzo/source2target-app-v2/backend_env/lib/python3.14/site-packages/django/db/models/query.py", line 366, in __len__
    self._fetch_all()
    ~~~~~~~~~~~~~~~^^
  File "/Users/david.galluzzo/source2target-app-v2/backend_env/lib/python3.14/site-packages/django/db/models/query.py", line 1949, in _fetch_all
    self._result_cache = list(self._iterable_class(self))
                         ~~~~^^^^^^^^^^^^^^^^^^^^^^^^^^^^
  File "/Users/david.galluzzo/source2target-app-v2/backend_env/lib/python3.14/site-packages/django/db/models/query.py", line 91, in __iter__
    results = compiler.execute_sql(
        chunked_fetch=self.chunked_fetch, chunk_size=self.chunk_size
    )
  File "/Users/david.galluzzo/source2target-app-v2/backend_env/lib/python3.14/site-packages/django/db/models/sql/compiler.py", line 1623, in execute_sql
    cursor.execute(sql, params)
    ~~~~~~~~~~~~~~^^^^^^^^^^^^^
  File "/Users/david.galluzzo/source2target-app-v2/backend_env/lib/python3.14/site-packages/django/db/backends/utils.py", line 122, in execute
    return super().execute(sql, params)
           ~~~~~~~~~~~~~~~^^^^^^^^^^^^^
  File "/Users/david.galluzzo/source2target-app-v2/backend_env/lib/python3.14/site-packages/django/db/backends/utils.py", line 79, in execute
    return self._execute_with_wrappers(
           ~~~~~~~~~~~~~~~~~~~~~~~~~~~^
        sql, params, many=False, executor=self._execute
        ^^^^^^^^^^^^^^^^^^^^^^^^^^^^^^^^^^^^^^^^^^^^^^^
    )
    ^
  File "/Users/david.galluzzo/source2target-app-v2/backend_env/lib/python3.14/site-packages/django/db/backends/utils.py", line 92, in _execute_with_wrappers
    return executor(sql, params, many, context)
  File "/Users/david.galluzzo/source2target-app-v2/backend_env/lib/python3.14/site-packages/django/db/backends/utils.py", line 100, in _execute
    with self.db.wrap_database_errors:
         ^^^^^^^^^^^^^^^^^^^^^^^^^^^^
  File "/Users/david.galluzzo/source2target-app-v2/backend_env/lib/python3.14/site-packages/django/db/utils.py", line 91, in __exit__
    raise dj_exc_value.with_traceback(traceback) from exc_value
  File "/Users/david.galluzzo/source2target-app-v2/backend_env/lib/python3.14/site-packages/django/db/backends/utils.py", line 105, in _execute
    return self.cursor.execute(sql, params)
           ~~~~~~~~~~~~~~~~~~~^^^^^^^^^^^^^
  File "/Users/david.galluzzo/source2target-app-v2/backend_env/lib/python3.14/site-packages/django/db/backends/sqlite3/base.py", line 360, in execute
    return super().execute(query, params)
           ~~~~~~~~~~~~~~~^^^^^^^^^^^^^^^
django.db.utils.OperationalError: no such table: auth_user
ERROR 2025-10-31 00:42:02,757 basehttp 37295 6167146496 "POST /api/accounts/auth/login/ HTTP/1.1" 500 195633
ERROR 2025-10-31 00:42:12,609 log 37295 6167146496 Internal Server Error: /api/accounts/auth/login/
Traceback (most recent call last):
  File "/Users/david.galluzzo/source2target-app-v2/backend_env/lib/python3.14/site-packages/django/db/backends/utils.py", line 105, in _execute
    return self.cursor.execute(sql, params)
           ~~~~~~~~~~~~~~~~~~~^^^^^^^^^^^^^
  File "/Users/david.galluzzo/source2target-app-v2/backend_env/lib/python3.14/site-packages/django/db/backends/sqlite3/base.py", line 360, in execute
    return super().execute(query, params)
           ~~~~~~~~~~~~~~~^^^^^^^^^^^^^^^
sqlite3.OperationalError: no such table: auth_user

The above exception was the direct cause of the following exception:

Traceback (most recent call last):
  File "/Users/david.galluzzo/source2target-app-v2/backend_env/lib/python3.14/site-packages/django/core/handlers/exception.py", line 55, in inner
    response = get_response(request)
  File "/Users/david.galluzzo/source2target-app-v2/backend_env/lib/python3.14/site-packages/django/core/handlers/base.py", line 197, in _get_response
    response = wrapped_callback(request, *callback_args, **callback_kwargs)
  File "/Users/david.galluzzo/source2target-app-v2/backend_env/lib/python3.14/site-packages/django/views/decorators/csrf.py", line 65, in _view_wrapper
    return view_func(request, *args, **kwargs)
  File "/Users/david.galluzzo/source2target-app-v2/backend_env/lib/python3.14/site-packages/django/views/generic/base.py", line 105, in view
    return self.dispatch(request, *args, **kwargs)
           ~~~~~~~~~~~~~^^^^^^^^^^^^^^^^^^^^^^^^^^
  File "/Users/david.galluzzo/source2target-app-v2/backend_env/lib/python3.14/site-packages/rest_framework/views.py", line 515, in dispatch
    response = self.handle_exception(exc)
  File "/Users/david.galluzzo/source2target-app-v2/backend_env/lib/python3.14/site-packages/rest_framework/views.py", line 475, in handle_exception
    self.raise_uncaught_exception(exc)
    ~~~~~~~~~~~~~~~~~~~~~~~~~~~~~^^^^^
  File "/Users/david.galluzzo/source2target-app-v2/backend_env/lib/python3.14/site-packages/rest_framework/views.py", line 486, in raise_uncaught_exception
    raise exc
  File "/Users/david.galluzzo/source2target-app-v2/backend_env/lib/python3.14/site-packages/rest_framework/views.py", line 512, in dispatch
    response = handler(request, *args, **kwargs)
  File "/Users/david.galluzzo/source2target-app-v2/backend/accounts/views.py", line 44, in post
    response = super().post(request, *args, **kwargs)
  File "/Users/david.galluzzo/source2target-app-v2/backend_env/lib/python3.14/site-packages/rest_framework_simplejwt/views.py", line 46, in post
    serializer.is_valid(raise_exception=True)
    ~~~~~~~~~~~~~~~~~~~^^^^^^^^^^^^^^^^^^^^^^
  File "/Users/david.galluzzo/source2target-app-v2/backend_env/lib/python3.14/site-packages/rest_framework/serializers.py", line 225, in is_valid
    self._validated_data = self.run_validation(self.initial_data)
                           ~~~~~~~~~~~~~~~~~~~^^^^^^^^^^^^^^^^^^^
  File "/Users/david.galluzzo/source2target-app-v2/backend_env/lib/python3.14/site-packages/rest_framework/serializers.py", line 447, in run_validation
    value = self.validate(value)
  File "/Users/david.galluzzo/source2target-app-v2/backend/accounts/serializers.py", line 36, in validate
    user = User.objects.get(email=email)
  File "/Users/david.galluzzo/source2target-app-v2/backend_env/lib/python3.14/site-packages/django/db/models/manager.py", line 87, in manager_method
    return getattr(self.get_queryset(), name)(*args, **kwargs)
           ~~~~~~~~~~~~~~~~~~~~~~~~~~~~~~~~~~^^^^^^^^^^^^^^^^^
  File "/Users/david.galluzzo/source2target-app-v2/backend_env/lib/python3.14/site-packages/django/db/models/query.py", line 629, in get
    num = len(clone)
  File "/Users/david.galluzzo/source2target-app-v2/backend_env/lib/python3.14/site-packages/django/db/models/query.py", line 366, in __len__
    self._fetch_all()
    ~~~~~~~~~~~~~~~^^
  File "/Users/david.galluzzo/source2target-app-v2/backend_env/lib/python3.14/site-packages/django/db/models/query.py", line 1949, in _fetch_all
    self._result_cache = list(self._iterable_class(self))
                         ~~~~^^^^^^^^^^^^^^^^^^^^^^^^^^^^
  File "/Users/david.galluzzo/source2target-app-v2/backend_env/lib/python3.14/site-packages/django/db/models/query.py", line 91, in __iter__
    results = compiler.execute_sql(
        chunked_fetch=self.chunked_fetch, chunk_size=self.chunk_size
    )
  File "/Users/david.galluzzo/source2target-app-v2/backend_env/lib/python3.14/site-packages/django/db/models/sql/compiler.py", line 1623, in execute_sql
    cursor.execute(sql, params)
    ~~~~~~~~~~~~~~^^^^^^^^^^^^^
  File "/Users/david.galluzzo/source2target-app-v2/backend_env/lib/python3.14/site-packages/django/db/backends/utils.py", line 122, in execute
    return super().execute(sql, params)
           ~~~~~~~~~~~~~~~^^^^^^^^^^^^^
  File "/Users/david.galluzzo/source2target-app-v2/backend_env/lib/python3.14/site-packages/django/db/backends/utils.py", line 79, in execute
    return self._execute_with_wrappers(
           ~~~~~~~~~~~~~~~~~~~~~~~~~~~^
        sql, params, many=False, executor=self._execute
        ^^^^^^^^^^^^^^^^^^^^^^^^^^^^^^^^^^^^^^^^^^^^^^^
    )
    ^
  File "/Users/david.galluzzo/source2target-app-v2/backend_env/lib/python3.14/site-packages/django/db/backends/utils.py", line 92, in _execute_with_wrappers
    return executor(sql, params, many, context)
  File "/Users/david.galluzzo/source2target-app-v2/backend_env/lib/python3.14/site-packages/django/db/backends/utils.py", line 100, in _execute
    with self.db.wrap_database_errors:
         ^^^^^^^^^^^^^^^^^^^^^^^^^^^^
  File "/Users/david.galluzzo/source2target-app-v2/backend_env/lib/python3.14/site-packages/django/db/utils.py", line 91, in __exit__
    raise dj_exc_value.with_traceback(traceback) from exc_value
  File "/Users/david.galluzzo/source2target-app-v2/backend_env/lib/python3.14/site-packages/django/db/backends/utils.py", line 105, in _execute
    return self.cursor.execute(sql, params)
           ~~~~~~~~~~~~~~~~~~~^^^^^^^^^^^^^
  File "/Users/david.galluzzo/source2target-app-v2/backend_env/lib/python3.14/site-packages/django/db/backends/sqlite3/base.py", line 360, in execute
    return super().execute(query, params)
           ~~~~~~~~~~~~~~~^^^^^^^^^^^^^^^
django.db.utils.OperationalError: no such table: auth_user
ERROR 2025-10-31 00:42:12,611 basehttp 37295 6167146496 "POST /api/accounts/auth/login/ HTTP/1.1" 500 195633
ERROR 2025-10-31 00:42:20,522 log 37295 6167146496 Internal Server Error: /api/accounts/auth/login/
Traceback (most recent call last):
  File "/Users/david.galluzzo/source2target-app-v2/backend_env/lib/python3.14/site-packages/django/db/backends/utils.py", line 105, in _execute
    return self.cursor.execute(sql, params)
           ~~~~~~~~~~~~~~~~~~~^^^^^^^^^^^^^
  File "/Users/david.galluzzo/source2target-app-v2/backend_env/lib/python3.14/site-packages/django/db/backends/sqlite3/base.py", line 360, in execute
    return super().execute(query, params)
           ~~~~~~~~~~~~~~~^^^^^^^^^^^^^^^
sqlite3.OperationalError: no such table: auth_user

The above exception was the direct cause of the following exception:

Traceback (most recent call last):
  File "/Users/david.galluzzo/source2target-app-v2/backend_env/lib/python3.14/site-packages/django/core/handlers/exception.py", line 55, in inner
    response = get_response(request)
  File "/Users/david.galluzzo/source2target-app-v2/backend_env/lib/python3.14/site-packages/django/core/handlers/base.py", line 197, in _get_response
    response = wrapped_callback(request, *callback_args, **callback_kwargs)
  File "/Users/david.galluzzo/source2target-app-v2/backend_env/lib/python3.14/site-packages/django/views/decorators/csrf.py", line 65, in _view_wrapper
    return view_func(request, *args, **kwargs)
  File "/Users/david.galluzzo/source2target-app-v2/backend_env/lib/python3.14/site-packages/django/views/generic/base.py", line 105, in view
    return self.dispatch(request, *args, **kwargs)
           ~~~~~~~~~~~~~^^^^^^^^^^^^^^^^^^^^^^^^^^
  File "/Users/david.galluzzo/source2target-app-v2/backend_env/lib/python3.14/site-packages/rest_framework/views.py", line 515, in dispatch
    response = self.handle_exception(exc)
  File "/Users/david.galluzzo/source2target-app-v2/backend_env/lib/python3.14/site-packages/rest_framework/views.py", line 475, in handle_exception
    self.raise_uncaught_exception(exc)
    ~~~~~~~~~~~~~~~~~~~~~~~~~~~~~^^^^^
  File "/Users/david.galluzzo/source2target-app-v2/backend_env/lib/python3.14/site-packages/rest_framework/views.py", line 486, in raise_uncaught_exception
    raise exc
  File "/Users/david.galluzzo/source2target-app-v2/backend_env/lib/python3.14/site-packages/rest_framework/views.py", line 512, in dispatch
    response = handler(request, *args, **kwargs)
  File "/Users/david.galluzzo/source2target-app-v2/backend/accounts/views.py", line 44, in post
    response = super().post(request, *args, **kwargs)
  File "/Users/david.galluzzo/source2target-app-v2/backend_env/lib/python3.14/site-packages/rest_framework_simplejwt/views.py", line 46, in post
    serializer.is_valid(raise_exception=True)
    ~~~~~~~~~~~~~~~~~~~^^^^^^^^^^^^^^^^^^^^^^
  File "/Users/david.galluzzo/source2target-app-v2/backend_env/lib/python3.14/site-packages/rest_framework/serializers.py", line 225, in is_valid
    self._validated_data = self.run_validation(self.initial_data)
                           ~~~~~~~~~~~~~~~~~~~^^^^^^^^^^^^^^^^^^^
  File "/Users/david.galluzzo/source2target-app-v2/backend_env/lib/python3.14/site-packages/rest_framework/serializers.py", line 447, in run_validation
    value = self.validate(value)
  File "/Users/david.galluzzo/source2target-app-v2/backend/accounts/serializers.py", line 36, in validate
    user = User.objects.get(email=email)
  File "/Users/david.galluzzo/source2target-app-v2/backend_env/lib/python3.14/site-packages/django/db/models/manager.py", line 87, in manager_method
    return getattr(self.get_queryset(), name)(*args, **kwargs)
           ~~~~~~~~~~~~~~~~~~~~~~~~~~~~~~~~~~^^^^^^^^^^^^^^^^^
  File "/Users/david.galluzzo/source2target-app-v2/backend_env/lib/python3.14/site-packages/django/db/models/query.py", line 629, in get
    num = len(clone)
  File "/Users/david.galluzzo/source2target-app-v2/backend_env/lib/python3.14/site-packages/django/db/models/query.py", line 366, in __len__
    self._fetch_all()
    ~~~~~~~~~~~~~~~^^
  File "/Users/david.galluzzo/source2target-app-v2/backend_env/lib/python3.14/site-packages/django/db/models/query.py", line 1949, in _fetch_all
    self._result_cache = list(self._iterable_class(self))
                         ~~~~^^^^^^^^^^^^^^^^^^^^^^^^^^^^
  File "/Users/david.galluzzo/source2target-app-v2/backend_env/lib/python3.14/site-packages/django/db/models/query.py", line 91, in __iter__
    results = compiler.execute_sql(
        chunked_fetch=self.chunked_fetch, chunk_size=self.chunk_size
    )
  File "/Users/david.galluzzo/source2target-app-v2/backend_env/lib/python3.14/site-packages/django/db/models/sql/compiler.py", line 1623, in execute_sql
    cursor.execute(sql, params)
    ~~~~~~~~~~~~~~^^^^^^^^^^^^^
  File "/Users/david.galluzzo/source2target-app-v2/backend_env/lib/python3.14/site-packages/django/db/backends/utils.py", line 122, in execute
    return super().execute(sql, params)
           ~~~~~~~~~~~~~~~^^^^^^^^^^^^^
  File "/Users/david.galluzzo/source2target-app-v2/backend_env/lib/python3.14/site-packages/django/db/backends/utils.py", line 79, in execute
    return self._execute_with_wrappers(
           ~~~~~~~~~~~~~~~~~~~~~~~~~~~^
        sql, params, many=False, executor=self._execute
        ^^^^^^^^^^^^^^^^^^^^^^^^^^^^^^^^^^^^^^^^^^^^^^^
    )
    ^
  File "/Users/david.galluzzo/source2target-app-v2/backend_env/lib/python3.14/site-packages/django/db/backends/utils.py", line 92, in _execute_with_wrappers
    return executor(sql, params, many, context)
  File "/Users/david.galluzzo/source2target-app-v2/backend_env/lib/python3.14/site-packages/django/db/backends/utils.py", line 100, in _execute
    with self.db.wrap_database_errors:
         ^^^^^^^^^^^^^^^^^^^^^^^^^^^^
  File "/Users/david.galluzzo/source2target-app-v2/backend_env/lib/python3.14/site-packages/django/db/utils.py", line 91, in __exit__
    raise dj_exc_value.with_traceback(traceback) from exc_value
  File "/Users/david.galluzzo/source2target-app-v2/backend_env/lib/python3.14/site-packages/django/db/backends/utils.py", line 105, in _execute
    return self.cursor.execute(sql, params)
           ~~~~~~~~~~~~~~~~~~~^^^^^^^^^^^^^
  File "/Users/david.galluzzo/source2target-app-v2/backend_env/lib/python3.14/site-packages/django/db/backends/sqlite3/base.py", line 360, in execute
    return super().execute(query, params)
           ~~~~~~~~~~~~~~~^^^^^^^^^^^^^^^
django.db.utils.OperationalError: no such table: auth_user
ERROR 2025-10-31 00:42:20,524 basehttp 37295 6167146496 "POST /api/accounts/auth/login/ HTTP/1.1" 500 195614
ERROR 2025-10-31 00:42:21,860 log 37295 6167146496 Internal Server Error: /api/accounts/auth/login/
Traceback (most recent call last):
  File "/Users/david.galluzzo/source2target-app-v2/backend_env/lib/python3.14/site-packages/django/db/backends/utils.py", line 105, in _execute
    return self.cursor.execute(sql, params)
           ~~~~~~~~~~~~~~~~~~~^^^^^^^^^^^^^
  File "/Users/david.galluzzo/source2target-app-v2/backend_env/lib/python3.14/site-packages/django/db/backends/sqlite3/base.py", line 360, in execute
    return super().execute(query, params)
           ~~~~~~~~~~~~~~~^^^^^^^^^^^^^^^
sqlite3.OperationalError: no such table: auth_user

The above exception was the direct cause of the following exception:

Traceback (most recent call last):
  File "/Users/david.galluzzo/source2target-app-v2/backend_env/lib/python3.14/site-packages/django/core/handlers/exception.py", line 55, in inner
    response = get_response(request)
  File "/Users/david.galluzzo/source2target-app-v2/backend_env/lib/python3.14/site-packages/django/core/handlers/base.py", line 197, in _get_response
    response = wrapped_callback(request, *callback_args, **callback_kwargs)
  File "/Users/david.galluzzo/source2target-app-v2/backend_env/lib/python3.14/site-packages/django/views/decorators/csrf.py", line 65, in _view_wrapper
    return view_func(request, *args, **kwargs)
  File "/Users/david.galluzzo/source2target-app-v2/backend_env/lib/python3.14/site-packages/django/views/generic/base.py", line 105, in view
    return self.dispatch(request, *args, **kwargs)
           ~~~~~~~~~~~~~^^^^^^^^^^^^^^^^^^^^^^^^^^
  File "/Users/david.galluzzo/source2target-app-v2/backend_env/lib/python3.14/site-packages/rest_framework/views.py", line 515, in dispatch
    response = self.handle_exception(exc)
  File "/Users/david.galluzzo/source2target-app-v2/backend_env/lib/python3.14/site-packages/rest_framework/views.py", line 475, in handle_exception
    self.raise_uncaught_exception(exc)
    ~~~~~~~~~~~~~~~~~~~~~~~~~~~~~^^^^^
  File "/Users/david.galluzzo/source2target-app-v2/backend_env/lib/python3.14/site-packages/rest_framework/views.py", line 486, in raise_uncaught_exception
    raise exc
  File "/Users/david.galluzzo/source2target-app-v2/backend_env/lib/python3.14/site-packages/rest_framework/views.py", line 512, in dispatch
    response = handler(request, *args, **kwargs)
  File "/Users/david.galluzzo/source2target-app-v2/backend/accounts/views.py", line 44, in post
    response = super().post(request, *args, **kwargs)
  File "/Users/david.galluzzo/source2target-app-v2/backend_env/lib/python3.14/site-packages/rest_framework_simplejwt/views.py", line 46, in post
    serializer.is_valid(raise_exception=True)
    ~~~~~~~~~~~~~~~~~~~^^^^^^^^^^^^^^^^^^^^^^
  File "/Users/david.galluzzo/source2target-app-v2/backend_env/lib/python3.14/site-packages/rest_framework/serializers.py", line 225, in is_valid
    self._validated_data = self.run_validation(self.initial_data)
                           ~~~~~~~~~~~~~~~~~~~^^^^^^^^^^^^^^^^^^^
  File "/Users/david.galluzzo/source2target-app-v2/backend_env/lib/python3.14/site-packages/rest_framework/serializers.py", line 447, in run_validation
    value = self.validate(value)
  File "/Users/david.galluzzo/source2target-app-v2/backend/accounts/serializers.py", line 36, in validate
    user = User.objects.get(email=email)
  File "/Users/david.galluzzo/source2target-app-v2/backend_env/lib/python3.14/site-packages/django/db/models/manager.py", line 87, in manager_method
    return getattr(self.get_queryset(), name)(*args, **kwargs)
           ~~~~~~~~~~~~~~~~~~~~~~~~~~~~~~~~~~^^^^^^^^^^^^^^^^^
  File "/Users/david.galluzzo/source2target-app-v2/backend_env/lib/python3.14/site-packages/django/db/models/query.py", line 629, in get
    num = len(clone)
  File "/Users/david.galluzzo/source2target-app-v2/backend_env/lib/python3.14/site-packages/django/db/models/query.py", line 366, in __len__
    self._fetch_all()
    ~~~~~~~~~~~~~~~^^
  File "/Users/david.galluzzo/source2target-app-v2/backend_env/lib/python3.14/site-packages/django/db/models/query.py", line 1949, in _fetch_all
    self._result_cache = list(self._iterable_class(self))
                         ~~~~^^^^^^^^^^^^^^^^^^^^^^^^^^^^
  File "/Users/david.galluzzo/source2target-app-v2/backend_env/lib/python3.14/site-packages/django/db/models/query.py", line 91, in __iter__
    results = compiler.execute_sql(
        chunked_fetch=self.chunked_fetch, chunk_size=self.chunk_size
    )
  File "/Users/david.galluzzo/source2target-app-v2/backend_env/lib/python3.14/site-packages/django/db/models/sql/compiler.py", line 1623, in execute_sql
    cursor.execute(sql, params)
    ~~~~~~~~~~~~~~^^^^^^^^^^^^^
  File "/Users/david.galluzzo/source2target-app-v2/backend_env/lib/python3.14/site-packages/django/db/backends/utils.py", line 122, in execute
    return super().execute(sql, params)
           ~~~~~~~~~~~~~~~^^^^^^^^^^^^^
  File "/Users/david.galluzzo/source2target-app-v2/backend_env/lib/python3.14/site-packages/django/db/backends/utils.py", line 79, in execute
    return self._execute_with_wrappers(
           ~~~~~~~~~~~~~~~~~~~~~~~~~~~^
        sql, params, many=False, executor=self._execute
        ^^^^^^^^^^^^^^^^^^^^^^^^^^^^^^^^^^^^^^^^^^^^^^^
    )
    ^
  File "/Users/david.galluzzo/source2target-app-v2/backend_env/lib/python3.14/site-packages/django/db/backends/utils.py", line 92, in _execute_with_wrappers
    return executor(sql, params, many, context)
  File "/Users/david.galluzzo/source2target-app-v2/backend_env/lib/python3.14/site-packages/django/db/backends/utils.py", line 100, in _execute
    with self.db.wrap_database_errors:
         ^^^^^^^^^^^^^^^^^^^^^^^^^^^^
  File "/Users/david.galluzzo/source2target-app-v2/backend_env/lib/python3.14/site-packages/django/db/utils.py", line 91, in __exit__
    raise dj_exc_value.with_traceback(traceback) from exc_value
  File "/Users/david.galluzzo/source2target-app-v2/backend_env/lib/python3.14/site-packages/django/db/backends/utils.py", line 105, in _execute
    return self.cursor.execute(sql, params)
           ~~~~~~~~~~~~~~~~~~~^^^^^^^^^^^^^
  File "/Users/david.galluzzo/source2target-app-v2/backend_env/lib/python3.14/site-packages/django/db/backends/sqlite3/base.py", line 360, in execute
    return super().execute(query, params)
           ~~~~~~~~~~~~~~~^^^^^^^^^^^^^^^
django.db.utils.OperationalError: no such table: auth_user
ERROR 2025-10-31 00:42:21,863 basehttp 37295 6167146496 "POST /api/accounts/auth/login/ HTTP/1.1" 500 195614
ERROR 2025-10-31 00:43:53,794 log 37295 6167146496 Internal Server Error: /api/accounts/auth/login/
Traceback (most recent call last):
  File "/Users/david.galluzzo/source2target-app-v2/backend_env/lib/python3.14/site-packages/django/db/backends/utils.py", line 105, in _execute
    return self.cursor.execute(sql, params)
           ~~~~~~~~~~~~~~~~~~~^^^^^^^^^^^^^
  File "/Users/david.galluzzo/source2target-app-v2/backend_env/lib/python3.14/site-packages/django/db/backends/sqlite3/base.py", line 360, in execute
    return super().execute(query, params)
           ~~~~~~~~~~~~~~~^^^^^^^^^^^^^^^
sqlite3.OperationalError: no such table: auth_user

The above exception was the direct cause of the following exception:

Traceback (most recent call last):
  File "/Users/david.galluzzo/source2target-app-v2/backend_env/lib/python3.14/site-packages/django/core/handlers/exception.py", line 55, in inner
    response = get_response(request)
  File "/Users/david.galluzzo/source2target-app-v2/backend_env/lib/python3.14/site-packages/django/core/handlers/base.py", line 197, in _get_response
    response = wrapped_callback(request, *callback_args, **callback_kwargs)
  File "/Users/david.galluzzo/source2target-app-v2/backend_env/lib/python3.14/site-packages/django/views/decorators/csrf.py", line 65, in _view_wrapper
    return view_func(request, *args, **kwargs)
  File "/Users/david.galluzzo/source2target-app-v2/backend_env/lib/python3.14/site-packages/django/views/generic/base.py", line 105, in view
    return self.dispatch(request, *args, **kwargs)
           ~~~~~~~~~~~~~^^^^^^^^^^^^^^^^^^^^^^^^^^
  File "/Users/david.galluzzo/source2target-app-v2/backend_env/lib/python3.14/site-packages/rest_framework/views.py", line 515, in dispatch
    response = self.handle_exception(exc)
  File "/Users/david.galluzzo/source2target-app-v2/backend_env/lib/python3.14/site-packages/rest_framework/views.py", line 475, in handle_exception
    self.raise_uncaught_exception(exc)
    ~~~~~~~~~~~~~~~~~~~~~~~~~~~~~^^^^^
  File "/Users/david.galluzzo/source2target-app-v2/backend_env/lib/python3.14/site-packages/rest_framework/views.py", line 486, in raise_uncaught_exception
    raise exc
  File "/Users/david.galluzzo/source2target-app-v2/backend_env/lib/python3.14/site-packages/rest_framework/views.py", line 512, in dispatch
    response = handler(request, *args, **kwargs)
  File "/Users/david.galluzzo/source2target-app-v2/backend/accounts/views.py", line 44, in post
    response = super().post(request, *args, **kwargs)
  File "/Users/david.galluzzo/source2target-app-v2/backend_env/lib/python3.14/site-packages/rest_framework_simplejwt/views.py", line 46, in post
    serializer.is_valid(raise_exception=True)
    ~~~~~~~~~~~~~~~~~~~^^^^^^^^^^^^^^^^^^^^^^
  File "/Users/david.galluzzo/source2target-app-v2/backend_env/lib/python3.14/site-packages/rest_framework/serializers.py", line 225, in is_valid
    self._validated_data = self.run_validation(self.initial_data)
                           ~~~~~~~~~~~~~~~~~~~^^^^^^^^^^^^^^^^^^^
  File "/Users/david.galluzzo/source2target-app-v2/backend_env/lib/python3.14/site-packages/rest_framework/serializers.py", line 447, in run_validation
    value = self.validate(value)
  File "/Users/david.galluzzo/source2target-app-v2/backend/accounts/serializers.py", line 36, in validate
    user = User.objects.get(email=email)
  File "/Users/david.galluzzo/source2target-app-v2/backend_env/lib/python3.14/site-packages/django/db/models/manager.py", line 87, in manager_method
    return getattr(self.get_queryset(), name)(*args, **kwargs)
           ~~~~~~~~~~~~~~~~~~~~~~~~~~~~~~~~~~^^^^^^^^^^^^^^^^^
  File "/Users/david.galluzzo/source2target-app-v2/backend_env/lib/python3.14/site-packages/django/db/models/query.py", line 629, in get
    num = len(clone)
  File "/Users/david.galluzzo/source2target-app-v2/backend_env/lib/python3.14/site-packages/django/db/models/query.py", line 366, in __len__
    self._fetch_all()
    ~~~~~~~~~~~~~~~^^
  File "/Users/david.galluzzo/source2target-app-v2/backend_env/lib/python3.14/site-packages/django/db/models/query.py", line 1949, in _fetch_all
    self._result_cache = list(self._iterable_class(self))
                         ~~~~^^^^^^^^^^^^^^^^^^^^^^^^^^^^
  File "/Users/david.galluzzo/source2target-app-v2/backend_env/lib/python3.14/site-packages/django/db/models/query.py", line 91, in __iter__
    results = compiler.execute_sql(
        chunked_fetch=self.chunked_fetch, chunk_size=self.chunk_size
    )
  File "/Users/david.galluzzo/source2target-app-v2/backend_env/lib/python3.14/site-packages/django/db/models/sql/compiler.py", line 1623, in execute_sql
    cursor.execute(sql, params)
    ~~~~~~~~~~~~~~^^^^^^^^^^^^^
  File "/Users/david.galluzzo/source2target-app-v2/backend_env/lib/python3.14/site-packages/django/db/backends/utils.py", line 122, in execute
    return super().execute(sql, params)
           ~~~~~~~~~~~~~~~^^^^^^^^^^^^^
  File "/Users/david.galluzzo/source2target-app-v2/backend_env/lib/python3.14/site-packages/django/db/backends/utils.py", line 79, in execute
    return self._execute_with_wrappers(
           ~~~~~~~~~~~~~~~~~~~~~~~~~~~^
        sql, params, many=False, executor=self._execute
        ^^^^^^^^^^^^^^^^^^^^^^^^^^^^^^^^^^^^^^^^^^^^^^^
    )
    ^
  File "/Users/david.galluzzo/source2target-app-v2/backend_env/lib/python3.14/site-packages/django/db/backends/utils.py", line 92, in _execute_with_wrappers
    return executor(sql, params, many, context)
  File "/Users/david.galluzzo/source2target-app-v2/backend_env/lib/python3.14/site-packages/django/db/backends/utils.py", line 100, in _execute
    with self.db.wrap_database_errors:
         ^^^^^^^^^^^^^^^^^^^^^^^^^^^^
  File "/Users/david.galluzzo/source2target-app-v2/backend_env/lib/python3.14/site-packages/django/db/utils.py", line 91, in __exit__
    raise dj_exc_value.with_traceback(traceback) from exc_value
  File "/Users/david.galluzzo/source2target-app-v2/backend_env/lib/python3.14/site-packages/django/db/backends/utils.py", line 105, in _execute
    return self.cursor.execute(sql, params)
           ~~~~~~~~~~~~~~~~~~~^^^^^^^^^^^^^
  File "/Users/david.galluzzo/source2target-app-v2/backend_env/lib/python3.14/site-packages/django/db/backends/sqlite3/base.py", line 360, in execute
    return super().execute(query, params)
           ~~~~~~~~~~~~~~~^^^^^^^^^^^^^^^
django.db.utils.OperationalError: no such table: auth_user
ERROR 2025-10-31 00:43:53,796 basehttp 37295 6167146496 "POST /api/accounts/auth/login/ HTTP/1.1" 500 195633
WARNING 2025-10-31 00:45:34,095 log 37295 13304360960 Unauthorized: /api/mapping/source-tables/
WARNING 2025-10-31 00:45:34,095 basehttp 37295 13304360960 "GET /api/mapping/source-tables/?analysis_status=completed HTTP/1.1" 401 58
INFO 2025-10-31 00:48:01,175 autoreload 37295 8539578688 /Users/david.galluzzo/source2target-app-v2/backend/accounts/views.py changed, reloading.
INFO 2025-10-31 00:48:01,636 autoreload 38127 8539578688 Watching for file changes with StatReloader
INFO 2025-10-31 00:48:02,196 databricks_service 38127 8539578688 Databricks Workspace Client initialized with token authentication
INFO 2025-10-31 00:48:21,158 autoreload 38127 8539578688 /Users/david.galluzzo/source2target-app-v2/backend/accounts/views.py changed, reloading.
INFO 2025-10-31 00:48:21,623 autoreload 38139 8539578688 Watching for file changes with StatReloader
INFO 2025-10-31 00:48:22,200 databricks_service 38139 8539578688 Databricks Workspace Client initialized with token authentication
INFO 2025-10-31 00:48:34,863 autoreload 38139 8539578688 /Users/david.galluzzo/source2target-app-v2/backend/accounts/urls.py changed, reloading.
INFO 2025-10-31 00:48:35,303 autoreload 38148 8539578688 Watching for file changes with StatReloader
INFO 2025-10-31 00:48:35,885 databricks_service 38148 8539578688 Databricks Workspace Client initialized with token authentication
INFO 2025-10-31 00:48:46,433 autoreload 38148 8539578688 /Users/david.galluzzo/source2target-app-v2/backend/accounts/urls.py changed, reloading.
INFO 2025-10-31 00:48:46,842 autoreload 38192 8539578688 Watching for file changes with StatReloader
INFO 2025-10-31 00:48:47,435 databricks_service 38192 8539578688 Databricks Workspace Client initialized with token authentication
INFO 2025-10-31 00:49:31,186 databricks_service 38515 8539578688 Databricks Workspace Client initialized with token authentication
INFO 2025-10-31 00:50:14,829 config 38192 6128398336 loading DEFAULT profile from ~/.databrickscfg: host, token
ERROR 2025-10-31 00:50:15,787 views 38192 6128398336 Error getting current user: no such table: auth_user
ERROR 2025-10-31 00:50:15,787 log 38192 6128398336 Internal Server Error: /api/accounts/current-user/
ERROR 2025-10-31 00:50:15,787 basehttp 38192 6128398336 "GET /api/accounts/current-user/ HTTP/1.1" 500 65
INFO 2025-10-31 00:50:55,173 config 38192 6128398336 loading DEFAULT profile from ~/.databrickscfg: host, token
ERROR 2025-10-31 00:50:55,754 views 38192 6128398336 Error getting current user: no such table: auth_user
ERROR 2025-10-31 00:50:55,755 log 38192 6128398336 Internal Server Error: /api/accounts/current-user/
ERROR 2025-10-31 00:50:55,755 basehttp 38192 6128398336 "GET /api/accounts/current-user/ HTTP/1.1" 500 65
INFO 2025-10-31 00:51:25,097 config 38192 6145798144 loading DEFAULT profile from ~/.databrickscfg: host, token
ERROR 2025-10-31 00:51:25,625 views 38192 6145798144 Error getting current user: no such table: auth_user
ERROR 2025-10-31 00:51:25,625 log 38192 6145798144 Internal Server Error: /api/accounts/current-user/
ERROR 2025-10-31 00:51:25,625 basehttp 38192 6145798144 "GET /api/accounts/current-user/ HTTP/1.1" 500 65
WARNING 2025-10-31 00:51:33,863 log 38192 6162624512 Unauthorized: /api/mapping/source-tables/test_connection/
WARNING 2025-10-31 00:51:33,863 basehttp 38192 6162624512 "GET /api/mapping/source-tables/test_connection/ HTTP/1.1" 401 58
INFO 2025-10-31 00:51:41,550 config 38192 6128398336 loading DEFAULT profile from ~/.databrickscfg: host, token
INFO 2025-10-31 00:51:41,567 autoreload 38192 8539578688 /Users/david.galluzzo/source2target-app-v2/backend/accounts/urls.py changed, reloading.
INFO 2025-10-31 00:51:41,974 autoreload 38719 8539578688 Watching for file changes with StatReloader
INFO 2025-10-31 00:51:42,497 databricks_service 38719 8539578688 Databricks Workspace Client initialized with token authentication
INFO 2025-10-31 00:52:37,724 config 38719 6130233344 loading DEFAULT profile from ~/.databrickscfg: host, token
ERROR 2025-10-31 00:52:38,269 views 38719 6130233344 Error getting current user: no such table: auth_user
ERROR 2025-10-31 00:52:38,270 log 38719 6130233344 Internal Server Error: /api/accounts/current-user/
ERROR 2025-10-31 00:52:38,270 basehttp 38719 6130233344 "GET /api/accounts/current-user/ HTTP/1.1" 500 65
INFO 2025-10-31 00:52:42,019 config 38719 6130233344 loading DEFAULT profile from ~/.databrickscfg: host, token
ERROR 2025-10-31 00:52:42,634 views 38719 6130233344 Error getting current user: no such table: auth_user
ERROR 2025-10-31 00:52:42,635 log 38719 6130233344 Internal Server Error: /api/accounts/current-user/
ERROR 2025-10-31 00:52:42,635 basehttp 38719 6130233344 "GET /api/accounts/current-user/ HTTP/1.1" 500 65
INFO 2025-10-31 00:53:19,856 config 38719 6130233344 loading DEFAULT profile from ~/.databrickscfg: host, token
ERROR 2025-10-31 00:53:20,390 views 38719 6130233344 Error getting current user: no such table: auth_user
ERROR 2025-10-31 00:53:20,390 log 38719 6130233344 Internal Server Error: /api/accounts/current-user/
ERROR 2025-10-31 00:53:20,390 basehttp 38719 6130233344 "GET /api/accounts/current-user/ HTTP/1.1" 500 65
INFO 2025-10-31 00:53:34,937 config 38719 6130233344 loading DEFAULT profile from ~/.databrickscfg: host, token
ERROR 2025-10-31 00:53:35,464 views 38719 6130233344 Error getting current user: no such table: auth_user
ERROR 2025-10-31 00:53:35,465 log 38719 6130233344 Internal Server Error: /api/accounts/current-user/
ERROR 2025-10-31 00:53:35,466 basehttp 38719 6130233344 "GET /api/accounts/current-user/ HTTP/1.1" 500 65
INFO 2025-10-31 00:55:18,796 config 38719 6130233344 loading DEFAULT profile from ~/.databrickscfg: host, token
ERROR 2025-10-31 00:55:19,371 views 38719 6130233344 Error getting current user: no such table: auth_user
ERROR 2025-10-31 00:55:19,371 log 38719 6130233344 Internal Server Error: /api/accounts/current-user/
ERROR 2025-10-31 00:55:19,371 basehttp 38719 6130233344 "GET /api/accounts/current-user/ HTTP/1.1" 500 65
INFO 2025-10-31 00:55:22,412 config 38719 6130233344 loading DEFAULT profile from ~/.databrickscfg: host, token
ERROR 2025-10-31 00:55:22,967 views 38719 6130233344 Error getting current user: no such table: auth_user
ERROR 2025-10-31 00:55:22,967 log 38719 6130233344 Internal Server Error: /api/accounts/current-user/
ERROR 2025-10-31 00:55:22,968 basehttp 38719 6130233344 "GET /api/accounts/current-user/ HTTP/1.1" 500 65
INFO 2025-10-31 00:55:42,084 config 38719 6147633152 loading DEFAULT profile from ~/.databrickscfg: host, token
ERROR 2025-10-31 00:55:42,680 views 38719 6147633152 Error getting current user: no such table: auth_user
ERROR 2025-10-31 00:55:42,680 log 38719 6147633152 Internal Server Error: /api/accounts/current-user/
ERROR 2025-10-31 00:55:42,681 basehttp 38719 6147633152 "GET /api/accounts/current-user/ HTTP/1.1" 500 65
INFO 2025-10-31 00:56:18,065 config 38719 6147633152 loading DEFAULT profile from ~/.databrickscfg: host, token
ERROR 2025-10-31 00:56:18,589 views 38719 6147633152 Error getting current user: no such table: auth_user
ERROR 2025-10-31 00:56:18,590 log 38719 6147633152 Internal Server Error: /api/accounts/current-user/
ERROR 2025-10-31 00:56:18,590 basehttp 38719 6147633152 "GET /api/accounts/current-user/ HTTP/1.1" 500 65
INFO 2025-10-31 00:57:11,115 config 38719 6147633152 loading DEFAULT profile from ~/.databrickscfg: host, token
ERROR 2025-10-31 00:57:11,688 views 38719 6147633152 Error getting current user: no such table: auth_user
ERROR 2025-10-31 00:57:11,688 log 38719 6147633152 Internal Server Error: /api/accounts/current-user/
ERROR 2025-10-31 00:57:11,689 basehttp 38719 6147633152 "GET /api/accounts/current-user/ HTTP/1.1" 500 65
INFO 2025-10-31 00:57:35,247 config 38719 6147633152 loading DEFAULT profile from ~/.databrickscfg: host, token
ERROR 2025-10-31 00:57:35,813 views 38719 6147633152 Error getting current user: no such table: auth_user
ERROR 2025-10-31 00:57:35,814 log 38719 6147633152 Internal Server Error: /api/accounts/current-user/
ERROR 2025-10-31 00:57:35,814 basehttp 38719 6147633152 "GET /api/accounts/current-user/ HTTP/1.1" 500 65
INFO 2025-10-31 00:57:40,220 config 38719 6147633152 loading DEFAULT profile from ~/.databrickscfg: host, token
ERROR 2025-10-31 00:57:40,841 views 38719 6147633152 Error getting current user: no such table: auth_user
ERROR 2025-10-31 00:57:40,841 log 38719 6147633152 Internal Server Error: /api/accounts/current-user/
ERROR 2025-10-31 00:57:40,842 basehttp 38719 6147633152 "GET /api/accounts/current-user/ HTTP/1.1" 500 65
INFO 2025-10-31 00:58:43,898 config 38719 6147633152 loading DEFAULT profile from ~/.databrickscfg: host, token
ERROR 2025-10-31 00:58:44,470 views 38719 6147633152 Error getting current user: no such table: auth_user
ERROR 2025-10-31 00:58:44,470 log 38719 6147633152 Internal Server Error: /api/accounts/current-user/
ERROR 2025-10-31 00:58:44,470 basehttp 38719 6147633152 "GET /api/accounts/current-user/ HTTP/1.1" 500 65
INFO 2025-10-31 00:59:53,611 config 38719 6147633152 loading DEFAULT profile from ~/.databrickscfg: host, token
ERROR 2025-10-31 00:59:54,148 views 38719 6147633152 Error getting current user: no such table: auth_user
ERROR 2025-10-31 00:59:54,148 log 38719 6147633152 Internal Server Error: /api/accounts/current-user/
ERROR 2025-10-31 00:59:54,148 basehttp 38719 6147633152 "GET /api/accounts/current-user/ HTTP/1.1" 500 65
INFO 2025-10-31 01:02:05,524 config 38719 6147633152 loading DEFAULT profile from ~/.databrickscfg: host, token
ERROR 2025-10-31 01:02:06,042 views 38719 6147633152 Error getting current user: no such table: auth_user
ERROR 2025-10-31 01:02:06,043 log 38719 6147633152 Internal Server Error: /api/accounts/current-user/
ERROR 2025-10-31 01:02:06,043 basehttp 38719 6147633152 "GET /api/accounts/current-user/ HTTP/1.1" 500 65
INFO 2025-10-31 01:04:09,457 config 38719 6147633152 loading DEFAULT profile from ~/.databrickscfg: host, token
ERROR 2025-10-31 01:04:10,076 views 38719 6147633152 Error getting current user: no such table: auth_user
ERROR 2025-10-31 01:04:10,077 log 38719 6147633152 Internal Server Error: /api/accounts/current-user/
ERROR 2025-10-31 01:04:10,077 basehttp 38719 6147633152 "GET /api/accounts/current-user/ HTTP/1.1" 500 65
INFO 2025-10-31 01:04:17,633 config 38719 6147633152 loading DEFAULT profile from ~/.databrickscfg: host, token
ERROR 2025-10-31 01:04:18,142 views 38719 6147633152 Error getting current user: no such table: auth_user
ERROR 2025-10-31 01:04:18,142 log 38719 6147633152 Internal Server Error: /api/accounts/current-user/
ERROR 2025-10-31 01:04:18,143 basehttp 38719 6147633152 "GET /api/accounts/current-user/ HTTP/1.1" 500 65
INFO 2025-10-31 01:08:36,499 config 38719 6147633152 loading DEFAULT profile from ~/.databrickscfg: host, token
ERROR 2025-10-31 01:08:37,082 views 38719 6147633152 Error getting current user: no such table: auth_user
ERROR 2025-10-31 01:08:37,082 log 38719 6147633152 Internal Server Error: /api/accounts/current-user/
ERROR 2025-10-31 01:08:37,082 basehttp 38719 6147633152 "GET /api/accounts/current-user/ HTTP/1.1" 500 65
INFO 2025-10-31 01:08:52,442 config 38719 6147633152 loading DEFAULT profile from ~/.databrickscfg: host, token
ERROR 2025-10-31 01:08:52,974 views 38719 6147633152 Error getting current user: no such table: auth_user
ERROR 2025-10-31 01:08:52,975 log 38719 6147633152 Internal Server Error: /api/accounts/current-user/
ERROR 2025-10-31 01:08:52,975 basehttp 38719 6147633152 "GET /api/accounts/current-user/ HTTP/1.1" 500 65
INFO 2025-10-31 01:14:37,703 config 38719 6130233344 loading DEFAULT profile from ~/.databrickscfg: host, token
ERROR 2025-10-31 01:14:38,349 views 38719 6130233344 Error getting current user: no such table: auth_user
ERROR 2025-10-31 01:14:38,350 log 38719 6130233344 Internal Server Error: /api/accounts/current-user/
ERROR 2025-10-31 01:14:38,350 basehttp 38719 6130233344 "GET /api/accounts/current-user/ HTTP/1.1" 500 65
INFO 2025-10-31 01:14:39,507 config 38719 6130233344 loading DEFAULT profile from ~/.databrickscfg: host, token
ERROR 2025-10-31 01:14:40,020 views 38719 6130233344 Error getting current user: no such table: auth_user
ERROR 2025-10-31 01:14:40,021 log 38719 6130233344 Internal Server Error: /api/accounts/current-user/
ERROR 2025-10-31 01:14:40,021 basehttp 38719 6130233344 "GET /api/accounts/current-user/ HTTP/1.1" 500 65
INFO 2025-10-31 01:17:03,259 config 38719 6130233344 loading DEFAULT profile from ~/.databrickscfg: host, token
ERROR 2025-10-31 01:17:03,880 views 38719 6130233344 Error getting current user: no such table: auth_user
ERROR 2025-10-31 01:17:03,881 log 38719 6130233344 Internal Server Error: /api/accounts/current-user/
ERROR 2025-10-31 01:17:03,881 basehttp 38719 6130233344 "GET /api/accounts/current-user/ HTTP/1.1" 500 65
INFO 2025-10-31 01:21:00,542 config 38719 6130233344 loading DEFAULT profile from ~/.databrickscfg: host, token
ERROR 2025-10-31 01:21:01,129 views 38719 6130233344 Error getting current user: no such table: auth_user
ERROR 2025-10-31 01:21:01,130 log 38719 6130233344 Internal Server Error: /api/accounts/current-user/
ERROR 2025-10-31 01:21:01,130 basehttp 38719 6130233344 "GET /api/accounts/current-user/ HTTP/1.1" 500 65
INFO 2025-10-31 01:21:09,751 basehttp 38719 6147633152 "GET /api/docs/swagger/ HTTP/1.1" 200 4675
INFO 2025-10-31 01:21:09,897 basehttp 38719 6147633152 "GET /api/docs/schema/ HTTP/1.1" 200 219099
INFO 2025-10-31 01:22:32,833 autoreload 38719 8539578688 /Users/david.galluzzo/source2target-app-v2/backend/settings.py changed, reloading.
INFO 2025-10-31 01:22:33,303 autoreload 42550 8539578688 Watching for file changes with StatReloader
INFO 2025-10-31 01:22:33,880 databricks_service 42550 8539578688 Databricks Workspace Client initialized with token authentication
INFO 2025-10-31 01:22:43,368 autoreload 42550 8539578688 /Users/david.galluzzo/source2target-app-v2/backend/urls.py changed, reloading.
INFO 2025-10-31 01:22:43,768 autoreload 42558 8539578688 Watching for file changes with StatReloader
INFO 2025-10-31 01:22:44,352 databricks_service 42558 8539578688 Databricks Workspace Client initialized with token authentication
INFO 2025-10-31 01:22:51,742 databricks_service 42572 8539578688 Databricks Workspace Client initialized with token authentication
INFO 2025-10-31 01:23:02,167 autoreload 42558 8539578688 /Users/david.galluzzo/source2target-app-v2/backend/configuration/urls.py changed, reloading.
INFO 2025-10-31 01:23:02,584 autoreload 42578 8539578688 Watching for file changes with StatReloader
INFO 2025-10-31 01:23:03,163 databricks_service 42578 8539578688 Databricks Workspace Client initialized with token authentication
INFO 2025-10-31 01:23:08,403 databricks_service 42592 8539578688 Databricks Workspace Client initialized with token authentication
INFO 2025-10-31 01:23:14,207 databricks_service 42615 8539578688 Databricks Workspace Client initialized with token authentication
INFO 2025-10-31 01:24:00,363 databricks_service 42677 8539578688 Databricks Workspace Client initialized with token authentication
INFO 2025-10-31 01:24:17,303 config 42578 6165180416 loading DEFAULT profile from ~/.databrickscfg: host, token
ERROR 2025-10-31 01:24:17,918 views 42578 6165180416 Error getting current user: type object 'Role' has no attribute 'PLATFORM_USER'
ERROR 2025-10-31 01:24:17,919 log 42578 6165180416 Internal Server Error: /api/accounts/current-user/
ERROR 2025-10-31 01:24:17,919 basehttp 42578 6165180416 "GET /api/accounts/current-user/ HTTP/1.1" 500 65
INFO 2025-10-31 01:26:18,392 config 42578 6165180416 loading DEFAULT profile from ~/.databrickscfg: host, token
ERROR 2025-10-31 01:26:19,010 views 42578 6165180416 Error getting current user: type object 'Role' has no attribute 'PLATFORM_USER'
ERROR 2025-10-31 01:26:19,011 log 42578 6165180416 Internal Server Error: /api/accounts/current-user/
ERROR 2025-10-31 01:26:19,011 basehttp 42578 6165180416 "GET /api/accounts/current-user/ HTTP/1.1" 500 65
WARNING 2025-10-31 01:26:19,747 log 42578 6165180416 Unauthorized: /api/config/settings/full/
WARNING 2025-10-31 01:26:19,747 basehttp 42578 6165180416 "GET /api/config/settings/full/ HTTP/1.1" 401 58
INFO 2025-10-31 01:26:44,049 autoreload 42578 8539578688 /Users/david.galluzzo/source2target-app-v2/backend/settings.py changed, reloading.
INFO 2025-10-31 01:26:44,484 autoreload 42869 8539578688 Watching for file changes with StatReloader
INFO 2025-10-31 01:26:45,033 databricks_service 42869 8539578688 Databricks Workspace Client initialized with token authentication
WARNING 2025-10-31 01:26:47,832 log 42869 6202863616 Unauthorized: /api/config/settings/full/
WARNING 2025-10-31 01:26:47,833 basehttp 42869 6202863616 "GET /api/config/settings/full/ HTTP/1.1" 401 58
INFO 2025-10-31 01:26:47,833 config 42869 6219689984 loading DEFAULT profile from ~/.databrickscfg: host, token
ERROR 2025-10-31 01:26:48,361 views 42869 6219689984 Error getting current user: type object 'Role' has no attribute 'PLATFORM_USER'
ERROR 2025-10-31 01:26:48,362 log 42869 6219689984 Internal Server Error: /api/accounts/current-user/
ERROR 2025-10-31 01:26:48,362 basehttp 42869 6219689984 "GET /api/accounts/current-user/ HTTP/1.1" 500 65
WARNING 2025-10-31 01:26:48,715 log 42869 6219689984 Unauthorized: /api/config/settings/full/
WARNING 2025-10-31 01:26:48,717 basehttp 42869 6219689984 "GET /api/config/settings/full/ HTTP/1.1" 401 58
INFO 2025-10-31 01:26:48,717 config 42869 6202863616 loading DEFAULT profile from ~/.databrickscfg: host, token
ERROR 2025-10-31 01:26:49,236 views 42869 6202863616 Error getting current user: type object 'Role' has no attribute 'PLATFORM_USER'
ERROR 2025-10-31 01:26:49,236 log 42869 6202863616 Internal Server Error: /api/accounts/current-user/
ERROR 2025-10-31 01:26:49,237 basehttp 42869 6202863616 "GET /api/accounts/current-user/ HTTP/1.1" 500 65
WARNING 2025-10-31 01:27:53,130 log 42869 6202863616 Unauthorized: /api/config/settings/full/
WARNING 2025-10-31 01:27:53,130 basehttp 42869 6202863616 "GET /api/config/settings/full/ HTTP/1.1" 401 58
INFO 2025-10-31 01:28:04,851 autoreload 42869 8539578688 /Users/david.galluzzo/source2target-app-v2/backend/configuration/views.py changed, reloading.
INFO 2025-10-31 01:28:05,342 autoreload 42941 8539578688 Watching for file changes with StatReloader
INFO 2025-10-31 01:28:05,901 databricks_service 42941 8539578688 Databricks Workspace Client initialized with token authentication
INFO 2025-10-31 01:28:14,306 autoreload 42941 8539578688 /Users/david.galluzzo/source2target-app-v2/backend/configuration/views.py changed, reloading.
INFO 2025-10-31 01:28:14,718 autoreload 42949 8539578688 Watching for file changes with StatReloader
INFO 2025-10-31 01:28:15,292 databricks_service 42949 8539578688 Databricks Workspace Client initialized with token authentication
INFO 2025-10-31 01:28:24,776 autoreload 42949 8539578688 /Users/david.galluzzo/source2target-app-v2/backend/configuration/views.py changed, reloading.
INFO 2025-10-31 01:28:25,222 autoreload 42973 8539578688 Watching for file changes with StatReloader
INFO 2025-10-31 01:28:25,787 databricks_service 42973 8539578688 Databricks Workspace Client initialized with token authentication
WARNING 2025-10-31 01:28:35,737 log 42973 6156562432 Unauthorized: /api/config/settings/full/
WARNING 2025-10-31 01:28:35,737 basehttp 42973 6156562432 "GET /api/config/settings/full/ HTTP/1.1" 401 58
INFO 2025-10-31 01:29:06,817 autoreload 42973 8539578688 /Users/david.galluzzo/source2target-app-v2/backend/configuration/views.py changed, reloading.
INFO 2025-10-31 01:29:07,209 autoreload 43110 8539578688 Watching for file changes with StatReloader
INFO 2025-10-31 01:29:07,734 databricks_service 43110 8539578688 Databricks Workspace Client initialized with token authentication
INFO 2025-10-31 01:37:25,677 config 43110 6126579712 loading DEFAULT profile from ~/.databrickscfg: host, token
ERROR 2025-10-31 01:37:26,486 views 43110 6126579712 Error getting current user: type object 'Role' has no attribute 'PLATFORM_USER'
ERROR 2025-10-31 01:37:26,487 log 43110 6126579712 Internal Server Error: /api/accounts/current-user/
ERROR 2025-10-31 01:37:26,487 basehttp 43110 6126579712 "GET /api/accounts/current-user/ HTTP/1.1" 500 65
INFO 2025-10-31 01:43:18,453 config 43110 6126579712 loading DEFAULT profile from ~/.databrickscfg: host, token
ERROR 2025-10-31 01:43:19,098 views 43110 6126579712 Error getting current user: type object 'Role' has no attribute 'PLATFORM_USER'
ERROR 2025-10-31 01:43:19,098 log 43110 6126579712 Internal Server Error: /api/accounts/current-user/
ERROR 2025-10-31 01:43:19,098 basehttp 43110 6126579712 "GET /api/accounts/current-user/ HTTP/1.1" 500 65
